Traceback (most recent call last):
  File "C:\Users\valer\Anaconda3\lib\site-packages\jupyter_cache\executors\utils.py", line 56, in single_nb_execution
    record_timing=False,
  File "C:\Users\valer\Anaconda3\lib\site-packages\nbclient\client.py", line 1112, in execute
    return NotebookClient(nb=nb, resources=resources, km=km, **kwargs).execute()
  File "C:\Users\valer\Anaconda3\lib\site-packages\nbclient\util.py", line 74, in wrapped
    return just_run(coro(*args, **kwargs))
  File "C:\Users\valer\Anaconda3\lib\site-packages\nbclient\util.py", line 53, in just_run
    return loop.run_until_complete(coro)
  File "C:\Users\valer\Anaconda3\lib\asyncio\base_events.py", line 584, in run_until_complete
    return future.result()
  File "C:\Users\valer\Anaconda3\lib\site-packages\nbclient\client.py", line 554, in async_execute
    cell, index, execution_count=self.code_cells_executed + 1
  File "C:\Users\valer\Anaconda3\lib\site-packages\nbclient\client.py", line 857, in async_execute_cell
    self._check_raise_for_error(cell, exec_reply)
  File "C:\Users\valer\Anaconda3\lib\site-packages\nbclient\client.py", line 760, in _check_raise_for_error
    raise CellExecutionError.from_cell_and_msg(cell, exec_reply_content)
nbclient.exceptions.CellExecutionError: An error occurred while executing the following cell:
------------------
frequency, wavenumber, momentum, energy = p1()

print(f"The frequency of a photon with wavelength 486.1 nm is {frequency} Hz.")
print(f"The wavenumber, nu-bar, of a photon with wavelength  486.1 nm is {wavenumber} cm^-1.")
print(f"The momentum of a photon with wavelength  486.1 nm is {momentum} kg m/s.")
print(f"The energy of a photon with wavelength  486.1 nm is {energy} Joules.")

assert(isinstance(frequency,float)), "Type Error: The frequency should be a float."
assert(isinstance(wavenumber,float)), "Type Error: The wavenumber should be a float."
assert(isinstance(momentum,float)), "Type Error: The momentum should be a float."
assert(isinstance(energy,float)), "Type Error: The energy should be a float."

------------------

[1;31m---------------------------------------------------------------------------[0m
[1;31mAssertionError[0m                            Traceback (most recent call last)
[1;32m<ipython-input-3-30089505871a>[0m in [0;36m<module>[1;34m[0m
[0;32m      6[0m [0mprint[0m[1;33m([0m[1;34mf"The energy of a photon with wavelength  486.1 nm is {energy} Joules."[0m[1;33m)[0m[1;33m[0m[1;33m[0m[0m
[0;32m      7[0m [1;33m[0m[0m
[1;32m----> 8[1;33m [1;32massert[0m[1;33m([0m[0misinstance[0m[1;33m([0m[0mfrequency[0m[1;33m,[0m[0mfloat[0m[1;33m)[0m[1;33m)[0m[1;33m,[0m [1;34m"Type Error: The frequency should be a float."[0m[1;33m[0m[1;33m[0m[0m
[0m[0;32m      9[0m [1;32massert[0m[1;33m([0m[0misinstance[0m[1;33m([0m[0mwavenumber[0m[1;33m,[0m[0mfloat[0m[1;33m)[0m[1;33m)[0m[1;33m,[0m [1;34m"Type Error: The wavenumber should be a float."[0m[1;33m[0m[1;33m[0m[0m
[0;32m     10[0m [1;32massert[0m[1;33m([0m[0misinstance[0m[1;33m([0m[0mmomentum[0m[1;33m,[0m[0mfloat[0m[1;33m)[0m[1;33m)[0m[1;33m,[0m [1;34m"Type Error: The momentum should be a float."[0m[1;33m[0m[1;33m[0m[0m

[1;31mAssertionError[0m: Type Error: The frequency should be a float.
AssertionError: Type Error: The frequency should be a float.

